<?xml version="1.0" ?>
<!-- =================================================================================== -->
<!-- |    This document was autogenerated by xacro from /home/hello-robot/calib_trail_ws/src/stretch_ros/stretch_description/urdf/stretch_description.xacro | -->
<!-- |    EDITING THIS FILE BY HAND IS NOT RECOMMENDED                                 | -->
<!-- =================================================================================== -->
<robot name="stretch">
  <link name="link_gripper">
    <inertial>
      <origin rpy="0 0 0" xyz="-0.0170229132730066 0.0131410320934285 -0.0371614759484659"/>
      <mass value="0.101902711393094"/>
      <inertia ixx="0.001" ixy="0" ixz="0" iyy="0.001" iyz="0" izz="0.001"/>
    </inertial>
    <visual>
      <origin rpy="0 0 0" xyz="0 0 0"/>
      <geometry>
        <mesh filename="package://stretch_description/meshes/link_gripper.STL"/>
      </geometry>
      <material name="">
        <color rgba="0.792156862745098 0.819607843137255 0.933333333333333 1"/>
      </material>
    </visual>
    <collision>
      <origin rpy="0 0 0" xyz="0 0 0"/>
      <geometry>
        <mesh filename="package://stretch_description/meshes/link_gripper.STL"/>
      </geometry>
    </collision>
  </link>
  <!-- rpy="3.1416 0 1.5708" -->
  <!-- rpy="0.0 0 1.5708" -->
  <joint name="joint_gripper" type="fixed">
    <origin rpy="3.14159 0 -1.5708" xyz="0 0 0"/>
    <parent link="link_wrist_yaw"/>
    <child link="link_gripper"/>
    <axis xyz="0 0 0"/>
  </joint>


  <link name="link_grasp_center">
  </link>
  <joint name="joint_grasp_center" type="fixed">
    <origin rpy="0 0 3.141579" xyz="-0.205478 0 -0.138154"/>
    <parent link="link_gripper"/>
    <child link="link_grasp_center"/>
  </joint>
  <!--<xacro:include filename="stretch_gripper_with_puller.xacro" />-->
  <!--<xacro:include filename="stretch_dry_erase_marker.xacro" />-->
  <link name="base_link">
    <inertial>
      <origin rpy="0 0 0" xyz="-0.11587 0.0019426 0.093621"/>
      <mass value="1.1912"/>
      <inertia ixx="0.0034667" ixy="-5.0568E-06" ixz="0.00042861" iyy="0.0052744" iyz="-5.766E-05" izz="0.0047945"/>
    </inertial>
    <visual>
      <origin rpy="0 0 0" xyz="0 0 0"/>
      <geometry>
        <mesh filename="package://stretch_description/meshes/base_link.STL"/>
      </geometry>
      <material name="">
        <color rgba="0.79216 0.81961 0.93333 1"/>
      </material>
    </visual>
    <collision>
      <origin rpy="0 0 0" xyz="0 0 0"/>
      <geometry>
        <mesh filename="package://stretch_description/meshes/base_link.STL"/>
      </geometry>
    </collision>
  </link>
  <link name="link_mast">
    <inertial>
      <origin rpy="0 0 0" xyz="2.0817E-17 0.7075 -2.7756E-17"/>
      <mass value="1.8285"/>
      <inertia ixx="0.0709854511954588" ixy="-0.00433428742758457" ixz="-0.000186110788697573" iyy="0.000437922053342648" iyz="-0.00288788257713431" izz="0.071104808501661"/>
    </inertial>
    <visual>
      <origin rpy="0 0 0" xyz="0 0 0"/>
      <geometry>
        <mesh filename="package://stretch_description/meshes/link_mast.STL"/>
      </geometry>
      <material name="">
        <color rgba="0.79216 0.81961 0.93333 1"/>
      </material>
    </visual>
    <collision>
      <origin rpy="0 0 0" xyz="0 0 0"/>
      <geometry>
        <mesh filename="package://stretch_description/meshes/link_mast.STL"/>
      </geometry>
    </collision>
  </link>
  <joint name="joint_mast" type="fixed">
    <origin rpy="1.5708 0 4.8006E-17" xyz="-0.067 0.135 0.0284"/>
    <parent link="link_base_translation"/>
    <child link="link_mast"/>
    <axis xyz="0 0 0"/>
  </joint>
  <link name="link_lift">
    <inertial>
      <origin rpy="0 0 0" xyz="-0.031727 0.038403 0.013361"/>
      <mass value="0.27218"/>
      <inertia ixx="0.00052571" ixy="0.00014899" ixz="-1.9258E-05" iyy="0.00030679" iyz="-6.2451E-06" izz="0.00037324"/>
    </inertial>
    <visual>
      <origin rpy="0 0 0" xyz="0 0 0"/>
      <geometry>
        <mesh filename="package://stretch_description/meshes/link_lift.STL"/>
      </geometry>
      <material name="">
        <color rgba="0.79216 0.81961 0.93333 1"/>
      </material>
    </visual>
    <collision>
      <origin rpy="0 0 0" xyz="0 0 0"/>
      <geometry>
        <mesh filename="package://stretch_description/meshes/link_lift.STL"/>
      </geometry>
    </collision>
  </link>
  <joint name="joint_lift" type="prismatic">
    <origin rpy="-1.5708 1.5708 0" xyz="-0.037385 0.1666 0"/>
    <parent link="link_mast"/>
    <child link="link_lift"/>
    <axis xyz="0 0 1"/>
    <!-- for now: hand copied range_m: from lift: from ~/repos/stretch_fleet/stretch-re1-1001/stretch_re1_factory_params.yaml -->
    <!--<limit effort="100" lower="0.0" upper="1.095" velocity="1.0"/>-->
    <!-- copied value did not reach the top of mesh model with GUI sliders and RViz -->
    <limit effort="100" lower="0.0" upper="1.1" velocity="1.0"/>
  </joint>
  <link name="link_arm_l4">
    <inertial>
      <origin rpy="0 0 0" xyz="-1.0146E-06 -1.9719E-05 -0.094738"/>
      <mass value="0.068095"/>
      <inertia ixx="0.0001256" ixy="-5.6914E-12" ixz="6.0647E-09" iyy="0.0001256" iyz="1.1787E-07" izz="1.1091E-10"/>
    </inertial>
    <visual>
      <origin rpy="0 0 0" xyz="0 0 0"/>
      <geometry>
        <mesh filename="package://stretch_description/meshes/link_arm_l4.STL"/>
      </geometry>
      <material name="">
        <color rgba="0.79216 0.81961 0.93333 1"/>
      </material>
    </visual>
    <collision>
      <origin rpy="0 0 0" xyz="0 0 0"/>
      <geometry>
        <mesh filename="package://stretch_description/meshes/link_arm_l4.STL"/>
      </geometry>
    </collision>
  </link>
  <joint name="joint_arm_l4" type="fixed">
    <origin rpy="1.5708 2.4721E-15 -1.5708" xyz="-0.2547 0 0"/>
    <parent link="link_lift"/>
    <child link="link_arm_l4"/>
    <axis xyz="0 0 0"/>
  </joint>
  <link name="link_arm_l3">
    <inertial>
      <origin rpy="0 0 0" xyz="-5.13853606326845E-07 -1.99844969271112E-05 -0.0971104963726614"/>
      <mass value="0.0628927381893134"/>
      <inertia ixx="0.001" ixy="0" ixz="0" iyy="0.001" iyz="0" izz="0.001"/>
    </inertial>
    <visual>
      <origin rpy="0 0 0" xyz="0 0 0"/>
      <geometry>
        <mesh filename="package://stretch_description/meshes/link_arm_l3.STL"/>
      </geometry>
      <material name="">
        <color rgba="0.792156862745098 0.819607843137255 0.933333333333333 1"/>
      </material>
    </visual>
    <collision>
      <origin rpy="0 0 0" xyz="0 0 0"/>
      <geometry>
        <mesh filename="package://stretch_description/meshes/link_arm_l3.STL"/>
      </geometry>
    </collision>
  </link>
  <joint name="joint_arm_l3" type="prismatic">
    <origin rpy="7.68831233799385E-30 2.36716479416092E-30 2.29652732251143E-17" xyz="0 0 0.013"/>
    <parent link="link_arm_l4"/>
    <child link="link_arm_l3"/>
    <axis xyz="0 0 1"/>
    <!-- 0.13 = 0.52/4-->
    <limit effort="100" lower="0.0" upper="0.13" velocity="1.0"/>
  </joint>
  <link name="link_arm_l2">
    <inertial>
      <origin rpy="0 0 0" xyz="-5.17421949435687E-07 -2.02045301450349E-05 -0.0968815475684904"/>
      <mass value="0.0571386353275368"/>
      <inertia ixx="0.001" ixy="0" ixz="0" iyy="0.001" iyz="0" izz="0.001"/>
    </inertial>
    <visual>
      <origin rpy="0 0 0" xyz="0 0 0"/>
      <geometry>
        <mesh filename="package://stretch_description/meshes/link_arm_l2.STL"/>
      </geometry>
      <material name="">
        <color rgba="0.792156862745098 0.819607843137255 0.933333333333333 1"/>
      </material>
    </visual>
    <collision>
      <origin rpy="0 0 0" xyz="0 0 0"/>
      <geometry>
        <mesh filename="package://stretch_description/meshes/link_arm_l2.STL"/>
      </geometry>
    </collision>
  </link>
  <joint name="joint_arm_l2" type="prismatic">
    <origin rpy="0 1.57655765344625E-30 -1.66533453693773E-16" xyz="0 0 0.013"/>
    <parent link="link_arm_l3"/>
    <child link="link_arm_l2"/>
    <axis xyz="0 0 1"/>
    <!-- 0.13 = 0.52/4-->
    <limit effort="100" lower="0.0" upper="0.13" velocity="1.0"/>
  </joint>
  <link name="link_arm_l1">
    <inertial>
      <origin rpy="0 0 0" xyz="-5.257E-07 -2.0482E-05 -0.096543"/>
      <mass value="0.051382"/>
      <inertia ixx="0.001" ixy="0" ixz="0" iyy="0.001" iyz="0" izz="0.001"/>
    </inertial>
    <visual>
      <origin rpy="0 0 0" xyz="0 0 0"/>
      <geometry>
        <mesh filename="package://stretch_description/meshes/link_arm_l1.STL"/>
      </geometry>
      <material name="">
        <color rgba="0.79216 0.81961 0.93333 1"/>
      </material>
    </visual>
    <collision>
      <origin rpy="0 0 0" xyz="0 0 0"/>
      <geometry>
        <mesh filename="package://stretch_description/meshes/link_arm_l1.STL"/>
      </geometry>
    </collision>
  </link>
  <joint name="joint_arm_l1" type="prismatic">
    <origin rpy="-7.63746778746202E-30 -7.88860905221012E-31 1.11022302462516E-16" xyz="0 0 0.0129999999999981"/>
    <parent link="link_arm_l2"/>
    <child link="link_arm_l1"/>
    <axis xyz="0 0 1"/>
    <!-- 0.13 = 0.52/4-->
    <limit effort="100" lower="0.0" upper="0.13" velocity="1.0"/>
  </joint>
  <link name="link_arm_l0">
    <inertial>
      <origin rpy="0 0 0" xyz="0.0270582141286185 -0.00189876414654466 -0.0377809018481181"/>
      <mass value="0.085003260946398"/>
      <inertia ixx="0.001" ixy="0" ixz="0" iyy="0.001" iyz="0" izz="0.001"/>
    </inertial>
    <visual>
      <origin rpy="0 0 0" xyz="0 0 0"/>
      <geometry>
        <mesh filename="package://stretch_description/meshes/link_arm_l0.STL"/>
      </geometry>
      <material name="">
        <color rgba="0.792156862745098 0.819607843137255 0.933333333333333 1"/>
      </material>
    </visual>
    <collision>
      <origin rpy="0 0 0" xyz="0 0 0"/>
      <geometry>
        <mesh filename="package://stretch_description/meshes/link_arm_l0.STL"/>
      </geometry>
    </collision>
  </link>
  <joint name="joint_arm_l0" type="prismatic">
    <origin rpy="7.63746778746202E-30 -3.80121128864402E-15 2.62707547767438E-15" xyz="0 0 -0.0137499999991968"/>
    <parent link="link_arm_l1"/>
    <child link="link_arm_l0"/>
    <axis xyz="0 0 1"/>
    <!-- 0.13 = 0.52/4-->
    <limit effort="100" lower="0.0" upper="0.13" velocity="1.0"/>
  </joint>
  <link name="link_wrist_yaw">
    <inertial>
      <origin rpy="0 0 0" xyz="2.20122392535771E-11 2.9317167880849E-05 -0.018966592644729"/>
      <mass value="0.0404746907425003"/>
      <inertia ixx="0.001" ixy="0" ixz="0" iyy="0.001" iyz="0" izz="0.001"/>
    </inertial>
    <visual>
      <origin rpy="0 0 0" xyz="0 0 0"/>
      <geometry>
        <mesh filename="package://stretch_description/meshes/link_wrist_yaw.STL"/>
      </geometry>
      <material name="">
        <color rgba="0.898039215686275 0.917647058823529 0.929411764705882 1"/>
      </material>
    </visual>
    <collision>
      <origin rpy="0 0 0" xyz="0 0 0"/>
      <geometry>
        <mesh filename="package://stretch_description/meshes/link_wrist_yaw.STL"/>
      </geometry>
    </collision>
  </link>
  <joint name="joint_wrist_yaw" type="revolute">
    <origin rpy="1.5708 4.2595E-14 2.6415E-15" xyz="0.0830000000000654 -0.0307500000000129 0"/>
    <parent link="link_arm_l0"/>
    <child link="link_wrist_yaw"/>
    <axis xyz="0 0 -1"/>
    <!--
      stowed to front ~225 deg: 3.15159 x 1.25 = 3.9395
      using 4.0
      stowed to back ~100 deg:  100 / 180 x 3.14159 = 1.7453
      using -1.75
    -->
    <limit effort="100" lower="-1.75" upper="4.0" velocity="1.0"/>
  </joint>

  <joint name="joint_base_translation" type="prismatic">
    <origin rpy="1.5708 4.2595E-14 2.6415E-15" xyz="0.0830000000000654 -0.0307500000000129 0"/>
    <parent link="base_link"/>
    <child link="link_base_translation"/>
    <axis xyz="1 0 0"/>
    <limit effort="100" lower="-1.0" upper="1.0" velocity="1.0"/>
  </joint>

  <link name="link_base_translation">
    <inertial>
    </inertial>
    <visual>
    </visual>
    <collision>
    </collision>
  </link>
 
  
  <material name="aluminum">
    <color rgba="0.5 0.5 0.5 1"/>
  </material>
  <material name="plastic">
    <color rgba="0.1 0.1 0.1 1"/>
  </material>
  <!-- camera body, with origin at bottom screw mount -->
  
</robot>

